[2025-02-08T08:33:30.311+0000] {taskinstance.py:1157} INFO - Dependencies all met for dep_context=non-requeueable deps ti=<TaskInstance: taxi_demand_prediction.scrape_flight_arrivals manual__2025-02-08T08:26:45.843525+00:00 [queued]>
[2025-02-08T08:33:30.337+0000] {taskinstance.py:1157} INFO - Dependencies all met for dep_context=requeueable deps ti=<TaskInstance: taxi_demand_prediction.scrape_flight_arrivals manual__2025-02-08T08:26:45.843525+00:00 [queued]>
[2025-02-08T08:33:30.347+0000] {taskinstance.py:1359} INFO - Starting attempt 2 of 4
[2025-02-08T08:33:30.484+0000] {taskinstance.py:1380} INFO - Executing <Task(PythonOperator): scrape_flight_arrivals> on 2025-02-08 08:26:45.843525+00:00
[2025-02-08T08:33:30.507+0000] {standard_task_runner.py:57} INFO - Started process 94 to run task
[2025-02-08T08:33:30.531+0000] {standard_task_runner.py:84} INFO - Running: ['***', 'tasks', 'run', 'taxi_demand_prediction', 'scrape_flight_arrivals', 'manual__2025-02-08T08:26:45.843525+00:00', '--job-id', '31', '--raw', '--subdir', 'DAGS_FOLDER/taxi_demand_pipeline.py', '--cfg-path', '/tmp/tmpvgfddt9q']
[2025-02-08T08:33:30.540+0000] {standard_task_runner.py:85} INFO - Job 31: Subtask scrape_flight_arrivals
[2025-02-08T08:33:30.806+0000] {task_command.py:415} INFO - Running <TaskInstance: taxi_demand_prediction.scrape_flight_arrivals manual__2025-02-08T08:26:45.843525+00:00 [running]> on host 170e21ff8f68
[2025-02-08T08:33:31.446+0000] {taskinstance.py:1660} INFO - Exporting env vars: AIRFLOW_CTX_DAG_OWNER='***' AIRFLOW_CTX_DAG_ID='taxi_demand_prediction' AIRFLOW_CTX_TASK_ID='scrape_flight_arrivals' AIRFLOW_CTX_EXECUTION_DATE='2025-02-08T08:26:45.843525+00:00' AIRFLOW_CTX_TRY_NUMBER='2' AIRFLOW_CTX_DAG_RUN_ID='manual__2025-02-08T08:26:45.843525+00:00'
[2025-02-08T08:33:36.144+0000] {taskinstance.py:1935} ERROR - Task failed with exception
Traceback (most recent call last):
  File "/home/airflow/.local/lib/python3.8/site-packages/airflow/operators/python.py", line 192, in execute
    return_value = self.execute_callable()
  File "/home/airflow/.local/lib/python3.8/site-packages/airflow/operators/python.py", line 209, in execute_callable
    return self.python_callable(*self.op_args, **self.op_kwargs)
  File "/opt/airflow/dags/scripts/skp_scraper.py", line 12, in scrape_flights
    driver.get(SKP_URL)
NameError: name 'SKP_URL' is not defined
[2025-02-08T08:33:36.211+0000] {taskinstance.py:1398} INFO - Marking task as UP_FOR_RETRY. dag_id=taxi_demand_prediction, task_id=scrape_flight_arrivals, execution_date=20250208T082645, start_date=20250208T083330, end_date=20250208T083336
[2025-02-08T08:33:36.361+0000] {standard_task_runner.py:104} ERROR - Failed to execute job 31 for task scrape_flight_arrivals (name 'SKP_URL' is not defined; 94)
[2025-02-08T08:33:36.674+0000] {local_task_job_runner.py:228} INFO - Task exited with return code 1
[2025-02-08T08:33:37.049+0000] {taskinstance.py:2776} INFO - 0 downstream tasks scheduled from follow-on schedule check
