[2025-02-08T08:26:57.490+0000] {taskinstance.py:1157} INFO - Dependencies all met for dep_context=non-requeueable deps ti=<TaskInstance: taxi_demand_prediction.scrape_flight_arrivals scheduled__2025-02-08T04:00:00+00:00 [queued]>
[2025-02-08T08:26:57.519+0000] {taskinstance.py:1157} INFO - Dependencies all met for dep_context=requeueable deps ti=<TaskInstance: taxi_demand_prediction.scrape_flight_arrivals scheduled__2025-02-08T04:00:00+00:00 [queued]>
[2025-02-08T08:26:57.520+0000] {taskinstance.py:1359} INFO - Starting attempt 1 of 4
[2025-02-08T08:26:57.592+0000] {taskinstance.py:1380} INFO - Executing <Task(PythonOperator): scrape_flight_arrivals> on 2025-02-08 04:00:00+00:00
[2025-02-08T08:26:57.601+0000] {standard_task_runner.py:57} INFO - Started process 573 to run task
[2025-02-08T08:26:57.679+0000] {standard_task_runner.py:84} INFO - Running: ['***', 'tasks', 'run', 'taxi_demand_prediction', 'scrape_flight_arrivals', 'scheduled__2025-02-08T04:00:00+00:00', '--job-id', '16', '--raw', '--subdir', 'DAGS_FOLDER/taxi_demand_pipeline.py', '--cfg-path', '/tmp/tmp7ihto0zg']
[2025-02-08T08:26:57.706+0000] {standard_task_runner.py:85} INFO - Job 16: Subtask scrape_flight_arrivals
[2025-02-08T08:26:58.188+0000] {task_command.py:415} INFO - Running <TaskInstance: taxi_demand_prediction.scrape_flight_arrivals scheduled__2025-02-08T04:00:00+00:00 [running]> on host 0ec2860535ef
[2025-02-08T08:26:58.767+0000] {taskinstance.py:1660} INFO - Exporting env vars: AIRFLOW_CTX_DAG_OWNER='***' AIRFLOW_CTX_DAG_ID='taxi_demand_prediction' AIRFLOW_CTX_TASK_ID='scrape_flight_arrivals' AIRFLOW_CTX_EXECUTION_DATE='2025-02-08T04:00:00+00:00' AIRFLOW_CTX_TRY_NUMBER='1' AIRFLOW_CTX_DAG_RUN_ID='scheduled__2025-02-08T04:00:00+00:00'
[2025-02-08T08:27:01.688+0000] {taskinstance.py:1935} ERROR - Task failed with exception
Traceback (most recent call last):
  File "/home/airflow/.local/lib/python3.8/site-packages/airflow/operators/python.py", line 192, in execute
    return_value = self.execute_callable()
  File "/home/airflow/.local/lib/python3.8/site-packages/airflow/operators/python.py", line 209, in execute_callable
    return self.python_callable(*self.op_args, **self.op_kwargs)
  File "/opt/airflow/dags/scripts/skp_scraper.py", line 12, in scrape_flights
    driver.get(SKP_URL)
NameError: name 'SKP_URL' is not defined
[2025-02-08T08:27:01.794+0000] {taskinstance.py:1398} INFO - Marking task as UP_FOR_RETRY. dag_id=taxi_demand_prediction, task_id=scrape_flight_arrivals, execution_date=20250208T040000, start_date=20250208T082657, end_date=20250208T082701
[2025-02-08T08:27:02.065+0000] {standard_task_runner.py:104} ERROR - Failed to execute job 16 for task scrape_flight_arrivals (name 'SKP_URL' is not defined; 573)
[2025-02-08T08:27:02.109+0000] {local_task_job_runner.py:228} INFO - Task exited with return code 1
[2025-02-08T08:27:02.191+0000] {taskinstance.py:2776} INFO - 0 downstream tasks scheduled from follow-on schedule check
