[2025-02-08T08:26:59.542+0000] {taskinstance.py:1157} INFO - Dependencies all met for dep_context=non-requeueable deps ti=<TaskInstance: taxi_demand_prediction.scrape_flight_arrivals scheduled__2025-02-08T05:00:00+00:00 [queued]>
[2025-02-08T08:26:59.574+0000] {taskinstance.py:1157} INFO - Dependencies all met for dep_context=requeueable deps ti=<TaskInstance: taxi_demand_prediction.scrape_flight_arrivals scheduled__2025-02-08T05:00:00+00:00 [queued]>
[2025-02-08T08:26:59.581+0000] {taskinstance.py:1359} INFO - Starting attempt 1 of 4
[2025-02-08T08:26:59.910+0000] {taskinstance.py:1380} INFO - Executing <Task(PythonOperator): scrape_flight_arrivals> on 2025-02-08 05:00:00+00:00
[2025-02-08T08:26:59.944+0000] {standard_task_runner.py:57} INFO - Started process 1235 to run task
[2025-02-08T08:26:59.968+0000] {standard_task_runner.py:84} INFO - Running: ['***', 'tasks', 'run', 'taxi_demand_prediction', 'scrape_flight_arrivals', 'scheduled__2025-02-08T05:00:00+00:00', '--job-id', '17', '--raw', '--subdir', 'DAGS_FOLDER/taxi_demand_pipeline.py', '--cfg-path', '/tmp/tmpoj09sh9s']
[2025-02-08T08:26:59.974+0000] {standard_task_runner.py:85} INFO - Job 17: Subtask scrape_flight_arrivals
[2025-02-08T08:27:00.292+0000] {task_command.py:415} INFO - Running <TaskInstance: taxi_demand_prediction.scrape_flight_arrivals scheduled__2025-02-08T05:00:00+00:00 [running]> on host 0ec2860535ef
[2025-02-08T08:27:00.802+0000] {taskinstance.py:1660} INFO - Exporting env vars: AIRFLOW_CTX_DAG_OWNER='***' AIRFLOW_CTX_DAG_ID='taxi_demand_prediction' AIRFLOW_CTX_TASK_ID='scrape_flight_arrivals' AIRFLOW_CTX_EXECUTION_DATE='2025-02-08T05:00:00+00:00' AIRFLOW_CTX_TRY_NUMBER='1' AIRFLOW_CTX_DAG_RUN_ID='scheduled__2025-02-08T05:00:00+00:00'
[2025-02-08T08:27:02.298+0000] {taskinstance.py:1935} ERROR - Task failed with exception
Traceback (most recent call last):
  File "/home/airflow/.local/lib/python3.8/site-packages/airflow/operators/python.py", line 192, in execute
    return_value = self.execute_callable()
  File "/home/airflow/.local/lib/python3.8/site-packages/airflow/operators/python.py", line 209, in execute_callable
    return self.python_callable(*self.op_args, **self.op_kwargs)
  File "/opt/airflow/dags/scripts/skp_scraper.py", line 12, in scrape_flights
    driver.get(SKP_URL)
NameError: name 'SKP_URL' is not defined
[2025-02-08T08:27:02.346+0000] {taskinstance.py:1398} INFO - Marking task as UP_FOR_RETRY. dag_id=taxi_demand_prediction, task_id=scrape_flight_arrivals, execution_date=20250208T050000, start_date=20250208T082659, end_date=20250208T082702
[2025-02-08T08:27:02.399+0000] {standard_task_runner.py:104} ERROR - Failed to execute job 17 for task scrape_flight_arrivals (name 'SKP_URL' is not defined; 1235)
[2025-02-08T08:27:02.478+0000] {local_task_job_runner.py:228} INFO - Task exited with return code 1
[2025-02-08T08:27:02.573+0000] {taskinstance.py:2776} INFO - 0 downstream tasks scheduled from follow-on schedule check
